Workbook

Sheet characters
A1: char_id | B1: display_name | C1: faction | D1: first_met_location | E1: first_appearance_beat | F1: icon | G1: body
A2: estelle | B2: Estelle Bright | C2: Bracer Guild | D2: bright_house | E2: fc_pro | F2: estelle1.png | G2: estelleFullBody1.webp
A3: joshua | B3: Joshua Bright | C3: Bracer Guild | D3: bright_house | E3: fc_pro | F3: joshua1.png | G3: joshuaFullBody1.png
A4: schera | B4: Scherazard Harvey | C4: Bracer Guild | D4: rolent_city | E4: fc_pro | F4: scherazard1.webp | G4: scherazardFullBody1.webp
A5: cassius | B5: Cassius Bright | C5: Bracer Guild | D5: bright_house | E5: fc_pro | F5: cassius1.png | G5: cassiusFullBody1.png
A6: josette | B6: Josette Haar | C6: Jenis Royal Academy | D6: rolent_city | E6: fc_pro | F6: josetteCapua1.png | G6: josetteFullBody1.webp
A7: alba | B7: Professor Alba | C7: Archeologist | D7: esmelas | E7: fc_pro | F7: weismann1.webp | G7: weismannFullBody1.webp
A8: morgan | B8: General Morgan | C8: Liberl Army | D8: haken | E8: fc_ch1 | F8: morgan1.webp | G8: morganFullBody1.webp
A9: olivier | B9: Erebonian Traveller | C9: Bard | D9: haken | E9: fc_ch1 | F9: olivier1.png | G9: olivierFullBody1.png
A10: agate | B10: Agate Crosner | C10: Bracer Guild | D10: ravennue | E10: fc_ch1 | F10: agate1.png | G10: agateFullBody1.webp
A11: alan | B11: Alan Richard | C11: Liberl Army | D11: bose_city | E11: fc_ch1 | F11: alan1.png | G11: alanFullBody1.png
A12: loewe | B12: THAT guy | C12: Unknown | D12: valleria_shore | E12: fc_ch1 | F12: loewe1.webp | G12: loeweFullBody1.webp

Sheet locations
A1: loc_id | B1: name | C1: parent_loc_id | D1: type | E1: map_x | F1: map_y | G1: show_name
A2: rolent | B2: Rolent | C2: liberl | D2: region
A3: rolent_city | B3: Rolent City | C3: rolent | D3: city | E3: 31.3 | F3: 68.9
A4: liberl | B4: Liberl | D4: nation
A5: esmelas | B5: Esmelas Tower | C5: rolent | D5: district | E5: 30.5 | F5: 67.7
A6: perzel | B6: Perzel Farm | C6: rolent | D6: district | E6: 30.1 | F6: 69.2 | G6: 1
A7: bright_house | B7: Bright Family House | C7: rolent | D7: district | E7: 31.3 | F7: 69.9 | G7: 1
A8: malga | B8: Malga Mine | C8: rolent | D8: district | E8: 31.1 | F8: 65.8
A9: mistwald | B9: Mistwald | C9: rolent | D9: district | E9: 31.2 | F9: 70.6 | G9: 1
A10: bose | B10: Bose | C10: liberl | D10: region
A11: bose_city | B11: Bose City | C11: bose | D11: city | E11: 26.3 | F11: 66.6
A12: haken | B12: Haken Gate | C12: bose | D12: district | E12: 25.9 | F12: 63.1
A13: nebel | B13: Nebel Valley | C13: bose | D13: district | E13: 28.9 | F13: 66.5 | G13: 1
A14: ravennue | B14: Ravennue Village | C14: bose | D14: district | E14: 24.3 | F14: 65.2
A15: amberl | B15: Amberl Tower | C15: bose | D15: district | E15: 26.2 | F15: 67.9
A16: valleria_shore | B16: Valleria Lakeshore | C16: bose | D16: district | E16: 26.8 | F16: 68.6 | G16: 1
A17: krone_pass | B17: Krone Pass | C17: bose | D17: district | E17: 21.8 | F17: 67.6 | G17: 1
A18: ruan | B18: Ruan | C18: liberl | D18: region
A19: ruan_city | B19: Ruan City | C19: ruan | D19: city | E19: 23.3 | F19: 72.7
A20: manoria | B20: Manoria | C20: ruan | D20: district | E20: 21.5 | F20: 71.5
A21: jenis | B21: Jenis Royal Academy | C21: ruan | D21: district | E21: 25.1 | F21: 70.6
A22: sapphirl | B22: Sapphirl Tower | C22: ruan | D22: district | E22: 23.6 | F22: 74.1
A23: letten | B23: Air Letten | C23: ruan | D23: district | E23: 24.3 | F23: 75 | G23: 1
A24: varenne | B24: Varenne Lighthouse | C24: ruan | D24: district | E24: 21.3 | F24: 73.4 | G24: 1
A25: mercia | B25: Mercia Orphanage | C25: ruan | D25: district | E25: 21.9 | F25: 70.4 | G25: 1

Sheet beats
A1: beat_id | B1: sequence | C1: chapter | D1: title | E1: default_location | F1: approx_date | G1: travel_mode
A2: fc_pro | B2: 10 | C2: Prologue | D2: Get sent to Rolent to pickup a newspaper for Cassius | E2: bright_house | F2: March 1202
A3: fc_pro | B3: 11 | C3: Prologue | D3: Going to Rolent | E3: rolent_city | F3: March 1202
A4: fc_pro | B4: 12 | C4: Prologue | D4: Doing Junior Bracer Test | E4: rolent_city | F4: March 1202
A5: fc_pro | B5: 13 | C5: Prologue | D5: Interrupted by Aina on the way home | E5: rolent_city | F5: March 1202
A6: fc_pro | B6: 14 | C6: Prologue | D6: Attempting to rescue children from Esmelas Tower | E6: esmelas | F6: March 1202
A7: fc_pro | B7: 15 | C7: Prologue | D7: Ambushed by monsters, Cassius comes to the rescue | E7: esmelas | F7: March 1202
A8: fc_pro | B8: 16 | C8: Prologue | D8: Heading back home | E8: bright_house | F8: March 1202
A9: fc_pro | B9: 17 | C9: Prologue | D9: Learned Cassius is leaving for work | E9: bright_house | F9: March 1202
A10: fc_pro | B10: 18 | C10: Prologue | D10: Heading to Perzel Farm for Bracer job | E10: perzel | F10: April 1202
A11: fc_pro | B11: 19 | C11: Prologue | D11: Dealing with crop detroying monsters | E11: perzel | F11: April 1202
A12: fc_pro | B12: 20 | C12: Prologue | D12: Heading back to Rolent | E12: rolent_city | F12: April 1202
A13: fc_pro | B13: 21 | C13: Prologue | D13: Learning about Esmelas Crystal that needs retrieving from Mayor Klaus | E13: rolent_city | F13: April 1202
... A69: fc_ch1 | B69: 77 | C69: Chapter 1 | D69: Olivier suggests sneaking into the ship, which somehow works | E69: amberl | F69: June 1202
A70: fc_ch1 | B70: 78 | C70: Chapter 1 | D70: Found themselves in Nebel Valley after boarding the ship, which was the Capua Sky Pirates' hideout | E70: nebel | F70: June 1202 | G70: air
A71: fc_ch1 | B71: 79 | C71: Chapter 1 | D71: Finding a way through the maze to rescue the hostages and defeat the Sky Bandits | E71: nebel | F71: June 1202
A72: fc_ch1 | B72: 80 | C72: Chapter 1 | D72: Rescued the hostages, fighting the Sky Pirates after they state how they would have killed the hostages after receiving the ransom | E72: nebel | F72: June 1202
A73: fc_ch1 | B73: 81 | C73: Chapter 1 | D73: Defeated the Capua Sky Pirates | E73: nebel | F73: June 1202
A74: fc_ch1 | B74: 82 | C74: Chapter 1 | D74: The Sky Bandit's leader, Josette's brother, says he has no memories of what happened after meeting THAT guy | E74: nebel | F74: June 1202
A75: fc_ch1 | B75: 83 | C75: Chapter 1 | D75: Alan and the intelligence Division appear as teh Capua Sky Bandits try to flee and arrests them | E75: nebel | F75: June 1202
A76: fc_ch1 | B76: 84 | C76: Chapter 1 | D76: Linde is rescued, but Cassius is nowhere to be found, the captain saying Cassis got off as soon as the linde took off | E76: nebel | F76: June 1202
A77: fc_ch1 | B77: 85 | C77: Chapter 1 | D77: Returning to Bose to report findings, received second recommendation letter | E77: bose_city | F77: June 1202
A78: fc_ch1 | B78: 86 | C78: Chapter 1 | D78: Received a parcel from Cassius urging them to keep climbing the ranks, and he cannot return until the queen's birthday ceremony | E78: bose_city | F78: June 1202
A79: fc_ch1 | B79: 87 | C79: Chapter 1 | D79: Also received a parcel intended for Cassius, with a black myserious orbment from someone named "K", and that he should take it to "R" | E79: bose_city | F79: June 1202
A80: fc_ch1 | B80: 88 | C80: Chapter 1 | D80: Deciding to go to Ruan to obtain the next recommendation letter from the guild | E80: bose_city | F80: June 1202
A81: fc_ch1 | B81: 89 | C81: Chapter 1 | D81: Part ways with Olivier and Scherazard who are going back to Rolent | E81: bose_city | F81: June 1202
A82: fc_ch1 | B82: 90 | C82: Chapter 1 | D82: After separating, Olivier is seen talking with someone about a mission on an orbment | E82: bose_city | F82: June 1202
... A85: fc_ch2 | B85: 93 | C85: Chapter 2 | D85: Stopping at the Krone Pass Checkpoint for the night | E85: krone_pass | F85: June 1202

Sheet appearances
A1: char_id | B1: join_beat | C1: join_sequence | D1: location | E1: leave_beat | F1: leave_sequence | G1: activity | H1: travel_mode
A2: estelle | B2: fc_pro | C2: =beats!B2 -> 10 | G2: Party leader
A3: joshua | B3: fc_pro | C3: =beats!B2 -> 10 | G3: Party leader
A4: cassius | B4: fc_pro | C4: =beats!B2 -> 10 | E4: fc_pro | F4: =beats!B2 -> 10 | G4: Sent children to buy newspaper
A5: schera | B5: fc_pro | C5: =beats!B3 -> 11 | E5: fc_pro | F5: =beats!B5 -> 13 | G5: Dealing with Bracer duties
A6: cassius | B6: fc_pro | C6: =beats!B7 -> 15 | E6: fc_pro | F6: =beats!B9 -> 17 | G6: On a work trip with the guild
A7: josette | B7: fc_pro | C7: =beats!B17 -> 25 | E7: fc_pro | F7: =beats!B18 -> 26 | G7: Speaking to Rolent's mayor
A8: alba | B8: fc_pro | C8: =beats!B20 -> 28 | E8: fc_pro | F8: =beats!B21 -> 29 | G8: Researching Tetracyclic Towers
A9: schera | B9: fc_pro | C9: =beats!B22 -> 30 | E9: fc_ch1 | F9: 50 | G9: Guiding Estelle and Josua on their missions
A10: josette | B10: fc_pro | C10: =beats!B25 -> 33 | D10: mistwald | E10: fc_pro | F10: =beats!B27 -> 35 | G10: Fled on airship with his brother
A11: schera | B11: fc_ch1 | C11: =beats!B32 -> 40 | E11: fc_ch1 | F11: =beats!B82 -> 90 | G11: Tagging along Estelle and Joshua on their search for Cassius
A12: olivier | B12: fc_ch1 | C12: =beats!B40 -> 48 | E12: fc_ch1 | F12: =beats!B41 -> 49 | G12: Got shooed out from the meeting with Morgan he tried to sneak into
A13: morgan | B13: fc_ch1 | C13: =beats!B40 -> 48 | E13: fc_ch1 | F13: =beats!B44 -> 52 | G13: Left after Olivier difused his argument with Scherazard
A14: olivier | B14: fc_ch1 | C14: =beats!B44 -> 52 | E14: fc_ch1 | F14: =beats!B46 -> 54 | G14: Leaves to sightsee Bose
A15: agate | B15: fc_ch1 | C15: =beats!B51 -> 59 | E15: fc_ch1 | F15: =beats!B51 -> 59 | G15: On a Bracer job
A16: morgan | B16: fc_ch1 | C16: =beats!B56 -> 64 | E16: fc_ch1 | F16: =beats!B57 -> 65 | G16: Arrested the Bracers beleiving they kidnapped the Linde
A17: olivier | B17: fc_ch1 | C17: =beats!B57 -> 65 | E17: fc_ch1 | F17: =beats!B63 -> 71 | G17: Helping the party to redeem himself for drinking Bose's most expensive wine
A18: josette | B18: fc_ch1 | C18: =beats!B59 -> 67 | D18: bose_city | E18: fc_ch1 | F18: =beats!B59 -> 67 | G18: Raided Bose with the Sky Bandits and stole almost everyone's valueable possesions
A19: alan | B19: fc_ch1 | C19: =beats!B61 -> 69 | E19: fc_ch1 | F19: =beats!B61 -> 69 | G19: Investigating the assault in Bose by the Capua Sky bandits
A20: olivier | B20: fc_ch1 | C20: =beats!B63 -> 71 | E20: fc_ch1 | F20: =beats!B63 -> 71 | G20: Got knocked out trying to outdrink Scherazard
A21: josette | B21: fc_ch1 | C21: =beats!B64 -> 72 | E21: fc_ch1 | F21: =beats!B66 -> 74 | G21: Preparing to head back to the Sky Bandit base
A22: loewe | B22: fc_ch1 | C22: =beats!B65 -> 73 | E22: fc_ch1 | F22: =beats!B66 -> 74 | G22: Left after informing the Sky Bandits that the ransom payment is coming
A23: olivier | B23: fc_ch1 | C23: =beats!B68 -> 76 | E23: fc_ch1 | F23: =beats!B82 -> 90 | G23: Accompanying the gang to the Sky Bandit hideout
A24: josette | B24: fc_ch1 | C24: =beats!B72 -> 80 | E24: fc_ch1 | F24: =beats!B75 -> 83 | G24: Taken away by the Intelligence Division
A25: alan | B25: fc_ch1 | C25: =beats!B75 -> 83 | E25: fc_ch1 | F25: =beats!B75 -> 83 | G25: Arrested the Capua Sky Bandits
A26: schera | B26: fc_ch1 | C26: =beats!B82 -> 90 | D26: rolent_city | E26: fc_ch1 | F26: =beats!B83 -> 91 | G26: Going to Rolent with Olivier | H26: air
A27: olivier | B27: fc_ch1 | C27: =beats!B82 -> 90 | D27: rolent_city | E27: fc_ch1 | F27: =beats!B83 -> 91 | G27: Going to Rolent with Scherazard | H27: air

Sheet codex
A1: char_id | B1: revealed_at_beat | C1: sequence | D1: entry_type | E1: text | F1: reveal_name | G1: icon | H1: body
A2: cassius | B2: fc_pro | C2: =beats!B2 -> 10 | D2: bio | E2: Widowed since the 100 day war
A3: cassius | B3: fc_pro | C3: =beats!B2 -> 10 | D3: bio | E3: Father of Estelle, adoptive father of Josua
A4: joshua | B4: fc_pro | C4: =beats!B2 -> 10 | D4: bio | E4: Adopted brother of Estelle
A5: estelle | B5: fc_pro | C5: =beats!B2 -> 10 | D5: bio | E5: Her mother died protecting her during the 100 day war
A6: schera | B6: fc_pro | C6: =beats!B4 -> 12 | D6: bio | E6: Bracer mentor for Estelle and Joshua
A7: cassius | B7: fc_pro | C7: =beats!B9 -> 17 | D7: bio | E7: S rank Bracer
A8: cassius | B8: fc_pro | C8: =beats!B9 -> 17 | D8: bio | E8: On a work trip with the Bracer Guild
A9: estelle | B9: fc_pro | C9: =beats!B9 -> 17 | D9: bio | E9: Doing the easier of the bracer jobs left over by Cassius with Joshua
A10: joshua | B10: fc_pro | C10: =beats!B9 -> 17 | D10: bio | E10: Doing the easier of the bracer jobs left over by Cassius with Estelle
A11: schera | B11: fc_pro | C11: =beats!B9 -> 17 | D11: bio | E11: Doing the hardest of the bracer jobs left by Cassius
A12: alba | B12: fc_pro | C12: =beats!B19 -> 27 | D12: bio | E12: Archeologist investigating the Tetracyclic towers
A13: josette | B13: fc_pro | C13: =beats!B24 -> 32 | D13: bio | E13: Faked being a Jenis Royal Academy student to appraoch Mayor Klaus
A14: josette | B14: fc_pro | C14: =beats!B24 -> 32 | D14: bio | E14: Attempted to steal the Esmelas Crystal that was going to be gifted to the Queen | F14: Josette Capua | G14: josetteCapua2.png | H14: josetteFullBody2.png
A15: josette | B15: fc_pro | C15: =beats!B24 -> 32 | D15: faction | E15: Capua Sky Bandits
A16: josette | B16: fc_pro | C16: =beats!B24 -> 32 | D16: former_faction | E16: Jenis Royal Academy (cover identity)
A17: cassius | B17: fc_pro | C17: =beats!B30 -> 38 | D17: bio | E17: Disappeared on missing airliner
A18: estelle | B18: fc_pro | C18: =beats!B32 -> 40 | D18: bio | E18: Going to Bose in search of Cassius
A19: joshua | B19: fc_pro | C19: =beats!B32 -> 40 | D19: bio | E19: Going to Bose in search of Cassius
A20: schera | B20: fc_pro | C20: =beats!B32 -> 40 | D20: bio | E20: Accompanying Estelle and Joshua to Bose on their search for Cassius
A21: morgan | B21: fc_ch1 | C21: =beats!B33 -> 41 | D21: bio | E21: General of the Liberl army
A22: morgan | B22: fc_ch1 | C22: =beats!B35 -> 43 | D22: bio | E22: Dislikes the guild, and is not sharing information about the disappeared airliner
A23: josette | B23: fc_ch1 | C23: =beats!B42 -> 50 | D23: bio | E23: Captured the Linde alongside the rest of the Sky Pirates
A24: schera | B24: fc_ch1 | C24: =beats!B43 -> 51 | D24: bio | E24: Believes the military is incompetent in situations like the Linde disappearance
A25: morgan | B25: fc_ch1 | C25: =beats!B43 -> 51 | D25: bio | E25: Believes the Guild is incomepetent in situations like the Linde disappearance
A26: olivier | B26: fc_ch1 | C26: =beats!B45 -> 53 | D26: bio | E26: Wandeing bard and musician from the Empire, impossible to have a normal conversation with | F26: Olivier Lenheim
A27: alba | B27: fc_ch1 | C27: =beats!B49 -> 57 | D27: bio | E27: Was rescued by Estelle and Joshua in Amberl Tower, but decides to return to Bose alone
A28: agate | B28: fc_ch1 | C28: =beats!B51 -> 59 | D28: bio | E28: Senior Bracer on a solo quest
A29: olivier | B29: fc_ch1 | C29: =beats!B58 -> 66 | D29: bio | E29: Arrested for drinking Bose's most expensive wine
A30: alan | B30: fc_ch1 | C30: =beats!B61 -> 69 | D30: bio | E30: Head of the Liber Army Intelligence Division
A31: schera | B31: fc_ch1 | C31: =beats!B63 -> 71 | D31: bio | E31: Heavy drinker
A32: olivier | B32: fc_ch1 | C32: =beats!B63 -> 71 | D32: bio | E32: Tried outdrinking Scherazard and got knocked out
A33: loewe | B33: fc_ch1 | C33: =beats!B65 -> 73 | D33: bio | E33: Josette's brother started acting weird after meeting him
A34: loewe | B34: fc_ch1 | C34: =beats!B65 -> 73 | D34: bio | E34: Assures the Capua Sky Bandits that the ransom payment is coming
A35: josette | B35: fc_ch1 | C35: =beats!B65 -> 73 | D35: bio | E35: Suspicious of THAT guy as his brother started acting weird after meeting him
A36: alan | B36: fc_ch1 | C36: =beats!B75 -> 83 | D36: bio | E36: Arrested the Capua Sky Bandits while they tried fleeing
A37: josette | B37: fc_ch1 | C37: =beats!B75 -> 83 | D37: bio | E37: Arrested by the Intelligence Division after attempting to flee from the Bracer Guild operation
A38: cassius | B38: fc_ch1 | C38: =beats!B76 -> 84 | D38: bio | E38: Never boarded the Linde, and has not been spotted since
A39: estelle | B39: fc_ch1 | C39: =beats!B77 -> 85 | D39: bio | E39: Received second recommendation letter
A40: joshua | B40: fc_ch1 | C40: =beats!B77 -> 85 | D40: bio | E40: Received second recommendation letter
...
